File: TensionLab.txt
     Force(N)        Displ(mm)     Strain(%)
             3      0.000000      0.000267
             3      0.000000      0.000267
             3      0.000000      0.000267
             3      0.000000      0.000267
             5      0.000000      0.000267
             3      0.000000      0.000267
             5      0.000000      0.000267
             5      0.000000      0.000267
             5      0.000000      0.000267
             5      0.000000      0.000267
             5      0.000000      0.000267
             5      0.000000     -0.000133
             5      0.000000      0.000000
          -100      0.000000      0.000000
             0      0.000000     -0.000133
             0      0.000000      0.000133
             0      0.000000      0.000133
             0      0.000000      0.000133
             0      0.000000      0.000133
             2      0.000000      0.000133
             2      0.000000      0.000267
             2      0.000000      0.000267
             2      0.000000      0.000267
             2      0.000000      0.000133
             2      0.000000      0.000267
            63      0.011000      0.001067
           118      0.047000      0.001200
           168      0.083000      0.001467
           257      0.118000      0.002267
           388      0.152000      0.004000
           545      0.189000      0.006133
           737      0.224000      0.008800
           977      0.259000      0.012400
          1262      0.293000      0.017067
          1583      0.329000      0.022533
          1927      0.365000      0.028533
          2318      0.401000      0.035067
          2735      0.436000      0.042267
          3202      0.471000      0.050400
          3713      0.507000      0.059333
          4263      0.543000      0.069200
          4818      0.578000      0.079067
          5417      0.615000      0.090000
          6008      0.650000      0.100800
          6640      0.686000      0.112533
          7270      0.721000      0.124400
          7907      0.757000      0.136667
          8560      0.792000      0.149333
          9202      0.827000      0.161867
          9860      0.863000      0.175067
         10523      0.898000      0.188400
         11183      0.933000      0.201867
         11862      0.969000      0.216400
         12528      1.004000      0.230667
         13197      1.040000      0.245733
         13862      1.076000      0.262000
         14510      1.112000      0.279200
         15140      1.147000      0.297200
         15747      1.182000      0.316533
         16342      1.218000      0.337733
         16905      1.253000      0.360400
         17455      1.289000      0.385333
         17982      1.325000      0.412400
         18463      1.360000      0.440400
         18907      1.395000      0.470133
         19350      1.431000      0.503333
         19748      1.466000      0.538000
         20123      1.502000      0.574533
         20468      1.538000      0.613733
         20788      1.575000      0.654533
         21067      1.609000      0.695200
         21328      1.645000      0.738533
         21565      1.681000      0.782667
         21780      1.716000      0.829600
         21973      1.752000      0.878667
         22143      1.787000      0.927600
         22293      1.823000      0.979333
         22430      1.860000      1.031733
         22547      1.895000      1.084667
         22647      1.930000      1.136933
         22740      1.967000      1.192133
         22815      2.001000      1.246800
         22878      2.037000      1.302533
         22935      2.072000      1.359600
         22983      2.107000      1.416933
         23028      2.143000      1.474533
         23058      2.178000      1.533333
         23087      2.214000      1.592800
         23112      2.248000      1.649733
         23132      2.285000      1.710800
         23153      2.320000      1.770533
         23168      2.356000      1.831600
         23183      2.391000      1.892400
         23195      2.427000      1.953467
         23207      2.464000      2.015600
         23215      2.499000      2.075867
         23230      2.536000      2.138533
         23243      2.570000      2.197867
         23255      2.605000      2.258000
         23260      2.640000      2.318400
         23270      2.675000      2.376667
         23283      2.711000      2.438667
         23293      2.746000      2.497733
         23307      2.781000      2.558533
         23315      2.816000      2.618133
         23330      2.852000      2.679200
         23340      2.888000      2.739867
         23353      2.923000      2.800267
         23360      2.958000      2.858800
         23377      2.995000      2.919600
         23390      3.030000      2.978400
         23405      3.065000      3.037733
         23415      3.100000      3.096400
         23425      3.135000      3.154933
         23437      3.170000      3.212400
         23452      3.205000      3.270533
         23462      3.240000      3.328533
         23475      3.275000      3.386667
         23488      3.310000      3.446000
         23503      3.348000      3.500000
         23513      3.383000      3.500000
         23370      3.408000      3.500000
         23077      3.407000      3.500000
         22945      3.407000      3.500000
         22868      3.407000      3.500000
         22813      3.407000      3.500000
         22768      3.407000      3.500000
         22733      3.407000      3.500000
         22703      3.407000      3.500000
         22680      3.407000      3.500000
         22658      3.407000      3.500000
         22640      3.407000      3.500000
         22622      3.407000      3.500000
         22743      3.416000      3.500000
         23473      3.452000      3.500000
         23720      3.488000      3.500000
         23717      3.524000      3.500000
         23675      3.559000      3.500000
         23653      3.594000      3.500000
         23647      3.629000      3.500000
         23643      3.665000      3.500000
         23640      3.700000      3.500000
         23647      3.736000      3.500000
         23658      3.771000      3.500000
         23667      3.807000      3.500000
         23673      3.843000      3.500000
         23687      3.878000      3.500000
         23695      3.914000      3.500000
         23705      3.949000      3.500000
         23712      3.985000      3.500000
         23727      4.021000      3.500000
         23737      4.056000      3.500000
         23748      4.092000      3.500000
         23757      4.127000      3.500000
         23762      4.161000      3.500000
         23773      4.198000      3.500000
         23787      4.234000      3.500000
         23795      4.269000      3.500000
         23808      4.306000      3.500000
         23815      4.341000      3.500000
         23828      4.376000      3.500000
         23835      4.412000      3.500000
         23845      4.448000      3.500000
         23860      4.484000      3.500000
         23870      4.519000      3.500000
         23875      4.555000      3.500000
         23885      4.590000      3.500000
         23893      4.626000      3.500000
         23903      4.662000      3.500000
         23912      4.697000      3.500000
         23925      4.734000      3.500000
         23928      4.769000      3.500000
         23940      4.804000      3.500000
         23948      4.840000      3.500000
         23955      4.876000      3.500000
         23967      4.912000      3.500000
         23975      4.946000      3.500000
         23987      4.982000      3.500000
         23997      5.017000      3.500000
         23998      5.051000      3.500000
         24012      5.087000      3.500000
         24013      5.122000      3.500000
         24025      5.159000      3.500000
         24032      5.193000      3.500000
         24040      5.229000      3.500000
         24048      5.264000      3.500000
         24058      5.299000      3.500000
         24065      5.334000      3.500000
         24075      5.369000      3.500000
         24082      5.404000      3.500000
         24095      5.440000      3.500000
         24105      5.476000      3.500000
         24112      5.511000      3.500000
         24118      5.547000      3.500000
         24130      5.583000      3.500000
         24143      5.619000      3.500000
         24152      5.654000      3.500000
         24162      5.689000      3.500000
         24175      5.725000      3.500000
         24187      5.761000      3.500000
         24195      5.796000      3.500000
         24205      5.831000      3.500000
         24218      5.867000      3.500000
         24233      5.902000      3.500000
         24243      5.937000      3.500000
         24252      5.973000      3.500000
         24262      6.008000      3.500000
         24272      6.044000      3.500000
         24285      6.079000      3.500000
         24295      6.115000      3.500000
         24303      6.150000      3.500000
         24315      6.186000      3.500000
         24328      6.222000      3.500000
         24330      6.257000      3.500000
         24347      6.294000      3.500000
         24355      6.328000      3.500000
         24367      6.364000      3.500000
         24373      6.399000      3.500000
         24385      6.433000      3.500000
         24390      6.469000      3.500000
         24402      6.504000      3.500000
         24407      6.540000      3.500000
         24423      6.575000      3.500000
         24428      6.610000      3.500000
         24443      6.646000      3.500000
         24452      6.682000      3.500000
         24460      6.717000      3.500000
         24472      6.753000      3.500000
         24485      6.790000      3.500000
         24498      6.825000      3.500000
         24510      6.860000      3.500000
         24518      6.896000      3.500000
         24532      6.933000      3.500000
         24543      6.967000      3.500000
         24557      7.003000      3.500000
         24568      7.038000      3.500000
         24578      7.072000      3.500000
         24592      7.108000      3.500000
         24605      7.144000      3.500000
         24617      7.180000      3.500000
         24628      7.215000      3.500000
         24645      7.252000      3.500000
         24657      7.287000      3.500000
         24665      7.322000      3.500000
         24677      7.357000      3.500000
         24688      7.393000      3.500000
         24698      7.428000      3.500000
         24713      7.464000      3.500000
         24728      7.499000      3.500000
         24737      7.535000      3.500000
         24748      7.571000      3.500000
         24762      7.606000      3.500000
         24772      7.641000      3.500000
         24785      7.676000      3.500000
         24803      7.713000      3.500000
         24810      7.747000      3.500000
         24825      7.782000      3.500000
         24837      7.818000      3.500000
         24852      7.853000      3.500000
         24863      7.889000      3.500000
         24875      7.924000      3.500000
         24890      7.959000      3.500000
         24902      7.995000      3.500000
         24915      8.031000      3.500000
         24930      8.065000      3.500000
         24938      8.100000      3.500000
         24953      8.136000      3.500000
         24967      8.173000      3.500000
         24983      8.208000      3.500000
         24997      8.244000      3.500000
         25007      8.279000      3.500000
         25020      8.315000      3.500000
         25032      8.351000      3.500000
         25045      8.387000      3.500000
         25060      8.423000      3.500000
         25072      8.458000      3.500000
         25085      8.494000      3.500000
         25093      8.529000      3.500000
         25105      8.564000      3.500000
         25120      8.600000      3.500000
         25130      8.635000      3.500000
         25148      8.671000      3.500000
         25157      8.707000      3.500000
         25167      8.743000      3.500000
         25178      8.779000      3.500000
         25192      8.815000      3.500000
         25202      8.851000      3.500000
         25215      8.886000      3.500000
         25228      8.921000      3.500000
         25242      8.956000      3.500000
         25250      8.991000      3.500000
         25265      9.026000      3.500000
         25277      9.061000      3.500000
         25292      9.096000      3.500000
         25305      9.131000      3.500000
         25322      9.166000      3.500000
         25332      9.201000      3.500000
         25343      9.236000      3.500000
         25358      9.272000      3.500000
         25373      9.308000      3.500000
         25387      9.344000      3.500000
         25398      9.379000      3.500000
         25412      9.415000      3.500000
         25425      9.450000      3.500000
         25440      9.485000      3.500000
         25450      9.521000      3.500000
         25462      9.556000      3.500000
         25477      9.592000      3.500000
         25492      9.626000      3.500000
         25505      9.662000      3.500000
         25513      9.696000      3.500000
         25523      9.732000      3.500000
         25533      9.767000      3.500000
         25547      9.802000      3.500000
         25557      9.837000      3.500000
         25573      9.873000      3.500000
         25582      9.909000      3.500000
         25595      9.944000      3.500000
         25607      9.979000      3.500000
         25618     10.014000      3.500000
         25630     10.050000      3.500000
         25645     10.086000      3.500000
         25660     10.120000      3.500000
         25673     10.156000      3.500000
         25685     10.191000      3.500000
         25700     10.227000      3.500000
         25710     10.263000      3.500000
         25727     10.299000      3.500000
         25740     10.335000      3.500000
         25755     10.370000      3.500000
         25765     10.405000      3.500000
         25780     10.441000      3.500000
         25793     10.477000      3.500000
         25807     10.511000      3.500000
         25822     10.546000      3.500000
         25837     10.582000      3.500000
         25847     10.617000      3.500000
         25862     10.652000      3.500000
         25870     10.688000      3.500000
         25882     10.723000      3.500000
         25897     10.759000      3.500000
         25905     10.794000      3.500000
         25918     10.829000      3.500000
         25928     10.865000      3.500000
         25940     10.900000      3.500000
         25947     10.936000      3.500000
         25962     10.972000      3.500000
         25970     11.008000      3.500000
         25975     11.042000      3.500000
         25990     11.078000      3.500000
         25993     11.114000      3.500000
         26007     11.149000      3.500000
         26010     11.184000      3.500000
         26023     11.220000      3.500000
         26032     11.256000      3.500000
         26047     11.291000      3.500000
         26055     11.327000      3.500000
         26070     11.361000      3.500000
         26078     11.397000      3.500000
         26093     11.434000      3.500000
         26112     11.469000      3.500000
         26125     11.506000      3.500000
         26142     11.541000      3.500000
         26155     11.576000      3.500000
         26170     11.612000      3.500000
         26187     11.647000      3.500000
         26203     11.682000      3.500000
         26218     11.718000      3.500000
         26235     11.754000      3.500000
         26242     11.790000      3.500000
         26257     11.825000      3.500000
         26270     11.860000      3.500000
         26288     11.897000      3.500000
         26293     11.932000      3.500000
         26303     11.968000      3.500000
         26312     12.003000      3.500000
         26323     12.038000      3.500000
         26330     12.073000      3.500000
         26338     12.110000      3.500000
         26347     12.145000      3.500000
         26357     12.180000      3.500000
         26358     12.215000      3.500000
         26367     12.249000      3.500000
         26372     12.285000      3.500000
         26375     12.320000      3.500000
         26387     12.356000      3.500000
         26393     12.391000      3.500000
         26398     12.426000      3.500000
         26405     12.461000      3.500000
         26413     12.497000      3.500000
         26420     12.532000      3.500000
         26435     12.567000      3.500000
         26445     12.603000      3.500000
         26457     12.638000      3.500000
         26475     12.674000      3.500000
         26483     12.709000      3.500000
         26502     12.745000      3.500000
         26515     12.780000      3.500000
         26535     12.815000      3.500000
         26555     12.850000      3.500000
         26567     12.886000      3.500000
         26583     12.921000      3.500000
         26598     12.956000      3.500000
         26612     12.991000      3.500000
         26632     13.027000      3.500000
         26643     13.062000      3.500000
         26660     13.099000      3.500000
         26670     13.133000      3.500000
         26685     13.168000      3.500000
         26697     13.203000      3.500000
         26708     13.239000      3.500000
         26718     13.274000      3.500000
         26728     13.309000      3.500000
         26742     13.345000      3.500000
         26750     13.381000      3.500000
         26750     13.417000      3.500000
         26763     13.452000      3.500000
         26763     13.487000      3.500000
         26770     13.523000      3.500000
         26773     13.558000      3.500000
         26773     13.595000      3.500000
         26777     13.630000      3.500000
         26775     13.665000      3.500000
         26777     13.703000      3.500000
         26780     13.738000      3.500000
         26782     13.774000      3.500000
         26783     13.809000      3.500000
         26782     13.845000      3.500000
         26783     13.880000      3.500000
         26788     13.916000      3.500000
         26790     13.952000      3.500000
         26792     13.988000      3.500000
         26797     14.024000      3.500000
         26798     14.059000      3.500000
         26800     14.095000      3.500000
         26802     14.130000      3.500000
         26808     14.167000      3.500000
         26805     14.201000      3.500000
         26800     14.237000      3.500000
         26790     14.272000      3.500000
         26787     14.307000      3.500000
         26797     14.343000      3.500000
         26820     14.377000      3.500000
         26843     14.412000      3.500000
         26873     14.447000      3.500000
         26905     14.483000      3.500000
         26928     14.520000      3.500000
         26957     14.554000      3.500000
         26980     14.589000      3.500000
         26997     14.624000      3.500000
         27023     14.658000      3.500000
         27043     14.695000      3.500000
         27065     14.731000      3.500000
         27078     14.765000      3.500000
         27093     14.801000      3.500000
         27108     14.836000      3.500000
         27122     14.873000      3.500000
         27130     14.907000      3.500000
         27143     14.943000      3.500000
         27153     14.979000      3.500000
         27165     15.014000      3.500000
         27172     15.050000      3.500000
         27178     15.086000      3.500000
         27188     15.121000      3.500000
         27202     15.157000      3.500000
         27207     15.193000      3.500000
         27215     15.229000      3.500000
         27225     15.264000      3.500000
         27238     15.299000      3.500000
         27247     15.335000      3.500000
         27255     15.370000      3.500000
         27267     15.406000      3.500000
         27273     15.442000      3.500000
         27280     15.477000      3.500000
         27280     15.513000      3.500000
         27280     15.549000      3.500000
         27272     15.584000      3.500000
         27255     15.620000      3.500000
         27220     15.655000      3.500000
         27183     15.692000      3.500000
         27153     15.727000      3.500000
         27140     15.761000      3.500000
         27135     15.796000      3.500000
         27138     15.833000      3.500000
         27148     15.868000      3.500000
         27153     15.903000      3.500000
         27162     15.939000      3.500000
         27168     15.973000      3.500000
         27175     16.009000      3.500000
         27183     16.044000      3.500000
         27192     16.080000      3.500000
         27190     16.115000      3.500000
         27202     16.150000      3.500000
         27202     16.186000      3.500000
         27210     16.221000      3.500000
         27215     16.257000      3.500000
         27220     16.292000      3.500000
         27232     16.329000      3.500000
         27237     16.364000      3.500000
         27243     16.400000      3.500000
         27252     16.435000      3.500000
         27262     16.470000      3.500000
         27272     16.505000      3.500000
         27280     16.540000      3.500000
         27287     16.575000      3.500000
         27292     16.611000      3.500000
         27295     16.647000      3.500000
         27300     16.682000      3.500000
         27303     16.718000      3.500000
         27315     16.753000      3.500000
         27332     16.789000      3.500000
         27353     16.825000      3.500000
         27372     16.862000      3.500000
         27395     16.896000      3.500000
         27427     16.931000      3.500000
         27455     16.967000      3.500000
         27472     17.002000      3.500000
         27500     17.039000      3.500000
         27520     17.074000      3.500000
         27537     17.110000      3.500000
         27553     17.144000      3.500000
         27565     17.180000      3.500000
         27567     17.214000      3.500000
         27555     17.250000      3.500000
         27513     17.286000      3.500000
         27455     17.320000      3.500000
         27407     17.357000      3.500000
         27387     17.392000      3.500000
         27382     17.428000      3.500000
         27380     17.463000      3.500000
         27377     17.498000      3.500000
         27385     17.533000      3.500000
         27382     17.569000      3.500000
         27385     17.605000      3.500000
         27390     17.641000      3.500000
         27392     17.677000      3.500000
         27393     17.712000      3.500000
         27392     17.746000      3.500000
         27390     17.783000      3.500000
         27395     17.818000      3.500000
         27398     17.853000      3.500000
         27395     17.889000      3.500000
         27392     17.924000      3.500000
         27388     17.960000      3.500000
         27387     17.996000      3.500000
         27388     18.031000      3.500000
         27387     18.067000      3.500000
         27385     18.103000      3.500000
         27385     18.138000      3.500000
         27382     18.172000      3.500000
         27373     18.207000      3.500000
         27380     18.242000      3.500000
         27372     18.278000      3.500000
         27375     18.313000      3.500000
         27373     18.349000      3.500000
         27368     18.385000      3.500000
         27363     18.420000      3.500000
         27363     18.456000      3.500000
         27357     18.492000      3.500000
         27355     18.527000      3.500000
         27352     18.563000      3.500000
         27345     18.598000      3.500000
         27337     18.633000      3.500000
         27332     18.668000      3.500000
         27318     18.704000      3.500000
         27310     18.739000      3.500000
         27300     18.774000      3.500000
         27285     18.810000      3.500000
         27268     18.845000      3.500000
         27248     18.880000      3.500000
         27225     18.915000      3.500000
         27200     18.950000      3.500000
         27172     18.986000      3.500000
         27142     19.021000      3.500000
         27113     19.058000      3.500000
         27077     19.093000      3.500000
         27045     19.129000      3.500000
         27003     19.163000      3.500000
         26958     19.200000      3.500000
         26917     19.235000      3.500000
         26875     19.272000      3.500000
         26825     19.307000      3.500000
         26773     19.342000      3.500000
         26712     19.378000      3.500000
         26653     19.414000      3.500000
         26598     19.449000      3.500000
         26528     19.484000      3.500000
         26463     19.521000      3.500000
         26395     19.555000      3.500000
         26320     19.591000      3.500000
         26243     19.625000      3.500000
         26167     19.660000      3.500000
         26077     19.696000      3.500000
         25997     19.732000      3.500000
         25900     19.767000      3.500000
         25808     19.802000      3.500000
         25705     19.838000      3.500000
         25603     19.873000      3.500000
         25502     19.908000      3.500000
         25387     19.943000      3.500000
         25277     19.978000      3.500000
         25155     20.015000      3.500000
         25037     20.049000      3.500000
         24912     20.084000      3.500000
         24778     20.120000      3.500000
         24642     20.155000      3.500000
         24500     20.191000      3.500000
         24355     20.226000      3.500000
         24210     20.262000      3.500000
         24048     20.298000      3.500000
         23888     20.333000      3.500000
         23723     20.369000      3.500000
         23553     20.404000      3.500000
         23378     20.439000      3.500000
         23195     20.475000      3.500000
         23010     20.510000      3.500000
         22817     20.545000      3.500000
         22618     20.580000      3.500000
         22417     20.615000      3.500000
         22192     20.651000      3.500000
         21978     20.686000      3.500000
         21742     20.723000      3.500000
         21512     20.758000      3.500000
         21260     20.794000      3.500000
         21008     20.829000      3.500000
         20737     20.865000      3.500000
         20470     20.900000      3.500000
         20202     20.934000      3.500000
         19907     20.971000      3.500000
         19600     21.006000      3.500000
         19288     21.042000      3.500000
         18960     21.077000      3.500000
         18622     21.113000      3.500000
         18262     21.148000      3.500000
         17893     21.183000      3.500000
         17497     21.219000      3.500000
         17075     21.255000      3.500000
         16625     21.290000      3.500000
           -37     21.310000      3.500000